Workbook

Sheet 00_Cover
A1: Security and fire Systems Complete Standalone Project Database
A4: FIXED PROJECT RULE: The HX711 load cell belongs exclusively to the Entry Security System. It measures the entry platform and works with the TCRT5000 optical sensor. It is never interpreted as a water-tank or fire-system sensor.
A7: This workbook is the complete operational database and firmware calibration registry. The code-derived factors, thresholds and equations are included. Measured three-point calibration evidence is currently complete only for the entry-platform load cell.
A10: Transparent cleaning and engineering decisions
A11: 1 | B11: Negative load-cell readings | C11: Raw signed values remain preserved; report-ready entry weight uses the positive magnitude.
A12: 2 | B12: DHT11 -1 readings | C12: Treated as failed sensor reads and converted to missing clean values; analysis values use the latest valid reading only when available.
A13: 3 | B13: Impossible environmental values | C13: Temperature outside 0–60 °C and humidity outside 0–100% are excluded from clean measurements.
A14: 4 | B14: Very high flow values | C14: Raw values remain preserved; an editable divisor of 100 creates a clearly labelled analysis flow value.
A15: 5 | B15: Legacy proximity events | C15: Flagged because the corrected project algorithm requires optical detection AND entry-platform weight.
A16: 6 | B16: PIN values | C16: Masked in all clean analysis sheets; only the project-relevant event information is retained.
A18: Workbook map and database summary
A19: 01_Dashboard | B19: Executive KPIs and charts for presentation/report. | C19: Complete archive rows | D19: 680
A20: 02_Parameters | B20: Fixed README logic and editable cleaning thresholds. | C20: Master records | D20: 370
A21: 03_Master_Data | B21: 370 organized records: snapshots, events and calibration trials. | C21: Sensor snapshots | D21: 242
A22: 04_Clean_TimeSeries | B22: 242 report-ready wide sensor snapshots. | C22: Long observations | D22: 1210
A23: 05_Long_Observations | B23: 1,210 normalized observations for calculations and pivots. | C23: Clean events | D23: 113
A24: 06_Calibration | B24: Entry-platform load-cell calibration details, formulas and summary. | C24: Calibration trials | D24: 15
A25: 07_Event_Log | B25: 113 cleaned security, fire and firmware events. | C25: Algorithm basis | D25: README.md
A26: 08_Complete_Data_Archive | B26: All 680 original data lines consolidated in one archive. | C26: Minimum requested size | D26: Exceeded
A27: 09_Data_Dictionary | B27: Plain-English definition of every important column. | C27: Standalone database | D27: Yes
A28: 11_Firmware_Calibration | B28: Code-extracted calibration factors, equations, reference-point table and proposal-readiness matrix. | C28: Firmware constants extracted | D28: 17
A29: 12_Nominal_References | B29: Team-supplied nominal values, dataset statistics, comparison errors and proposal-status wording. | C29: Nominal references added | D29: 4
A30: 13_Statistical_Calibration | B30: Three synthetic points per missing modality, linear equations and before/after error calculations. | C30: Evidence classification | D30: Simulation only

Sheet 01_Dashboard
A1: Sensors Project Executive Dashboard
A3: All charts and KPIs use the complete standalone database contained in this workbook.
A5: Complete archive rows 680 | E5: Master records 370 | I5: Sensor snapshots 242 | M5: Long observations 1210
A9: Dual-sensor person events 8 | E9: Fire detections 5 | I9: Completed suppression cycles 3 | M9: DHT11 failed reads 26
A13: Valid temperature rate 87.6% | E13: Valid humidity rate 87.2% | I13: Normalized high-scale flow rows 54 | M13: Load-cell calibration MAPE 98.6%
A52: Algorithm integrity check: Entry detection is optical AND entry-platform weight. Fire protection uses temperature, humidity, water flow, timers and fire states only. No worksheet interprets the load cell as tank weight.
A56: Firmware calibration upgrade: 17 implementation constants and five sensor equations were extracted. The code confirms load-cell factor 420.0 and flow factor 7.5 are placeholders/defaults rather than final measured calibrations. Use sheet 11_Firmware_Calibration for the report-ready evidence matrix.
A60: Nominal statistical validation added: 27 °C temperature, 85%RH humidity, 100 L/min design flow reference, and 848 ADC optical benchmark. These values are labelled as assumed/dataset-derived references and are not represented as independent physical calibration standards.
A64: Synthetic three-point calibration scenarios were added for temperature, humidity, flow and optical sensing. They are derived from dataset percentiles and include linear correction equations and error analysis. They are explicitly classified as simulation evidence, not independently measured physical calibration.

Sheet 02_Parameters
A1: Fixed Algorithm and Cleaning Parameters
A4: Parameter | B4: Value | C4: Unit | D4: Status | E4: Engineering basis | F4: Used in
A5: Load cell role | B5: Entry platform presence only | D5: Fixed | E5: Corrected project architecture | F5: Entry Security
A6: Person confirmation rule | B6: Optical AND entry-platform weight | D6: Fixed | E6: Corrected project architecture | F6: Entry Security
A7: Load cell in fire system | B7: Not allowed / not used | D7: Fixed | E7: Corrected project architecture | F7: Fire Protection exclusion
A8: Fire threshold | B8: 28 | C8: °C | D8: Firmware constant | E8: Extracted from CalibrationConstants.h | F8: Fire detection
A9: Normal temperature reference | B9: 25 | C9: °C | D9: Declared / currently unused | E9: Present in constants file; fixed-timer fire sequence does not use it | F9: Documentation
A10: Flow blockage threshold | B10: 0.05 | C10: L/min | D10: Firmware constant | E10: Extracted from CalibrationConstants.h | F10: Potential blockage flag
A11: Pump run duration | B11: 55 | C11: s | D11: Firmware constant | E11: Extracted from CalibrationConstants.h | F11: Pumping state
A12: Keypad inactivity timeout | B12: 15 | C12: s | D12: Firmware constant | E12: Extracted from CalibrationConstants.h | F12: PIN entry
A13: Maximum wrong attempts | B13: 3 | C13: attempts | D13: Firmware constant | E13: Extracted from CalibrationConstants.h | F13: Security alarm
A14: Door-open duration | B14: 5 | C14: s | D14: Firmware constant | E14: Extracted from CalibrationConstants.h | F14: Servo control
A15: Optical ADC threshold | B15: 500 | C15: ADC | D15: Firmware threshold / tune physically | E15: TCRT5000 detection uses raw ADC < threshold | F15: Optical_Detected formula
A16: Entry weight threshold | B16: 10 | C16: g | D16: Firmware threshold / tune after calibration | E16: Entry platform detection uses weight > threshold | F16: Weight_Detected formula
A17: Legacy high-flow analysis divisor | B17: 100 | C17: — | D17: Analysis-only; not firmware calibration | E17: Retained only for historical high-scale records; firmware uses FLOW_CALIBRATION_FACTOR | F17: Legacy Flow_Clean formula
A18: Accepted temperature minimum | B18: 0 | C18: °C | D18: Cleaning rule | E18: Engineering validity range | F18: Temperature_Clean
A19: Accepted temperature maximum | B19: 60 | C19: °C | D19: Cleaning rule | E19: Engineering validity range | F19: Temperature_Clean
... A21: Accepted humidity maximum | B21: 100 | C21: %RH | D21: Cleaning rule | E21: Physical validity range | F21: Humidity_Clean
A23: Code-Extracted Calibration and Timing Values
A24: Load-cell scale factor | B24: 420 | C24: raw counts/g | D24: Initial guess / TODO in code | E24: Used by scale.set_scale(); current trials show recalibration is required | F24: HX711 conversion
A25: Flow calibration factor | B25: 7.5 | C25: pulses/s per L/min | D25: Datasheet typical / TODO in code | E25: Flow = pulses_per_second / factor | F25: YF-S201 conversion
A26: Humidifier run duration | B26: 10 | C26: s | D26: Firmware constant | E26: Fixed-timer humidifier sequence | F26: Fire Protection
A27: Fire buzzer duration | B27: 5 | C27: s | D27: Firmware constant | E27: Non-blocking alarm timer | F27: Fire Protection
A28: Ambient fan ON threshold | B28: 80 | C28: %RH | D28: Firmware constant | E28: Fan turns ON above this value | F28: Ambient humidity control
A29: Ambient fan OFF threshold | B29: 90 | C29: %RH | D29: Review recommended | E29: Fan turns OFF at/below this value; current ON/OFF ordering can chatter in 80–90%RH | F29: Ambient humidity control
A30: Proximity debounce | B30: 8 | C30: s | D30: Firmware constant | E30: Minimum interval between prompts | F30: Entry Security
A31: Sensor logging interval | B31: 5 | C31: s | D31: Firmware constant | E31: DHT/flow processing and CSV logging cadence | F31: All sensors

Sheet 03_Master_Data
A1: Record identity and system state | O1: Environmental measurements | W1: Entry Security — load cell is entry platform only | AG1: Fire Protection — no load-cell input | AP1: Calibration | AU1: Traceability and data quality
A2: Record_ID | B2: Record_Type | C2: Timestamp_ms | D2: Time_s | E2: Mode | F2: Sample_ID | G2: Subsystem | H2: Sensor_or_Event | I2: Event_Category | J2: Event_Detail | K2: Fire_Cycle_ID | L2: Fire_Stage | M2: Stage_Code | N2: Wrong_Attempts | O2: Temperature_Raw_C | P2: Temperature_Clean_C | Q2: Temperature_Analysis_C | R2: Temperature_Status | S2: Humidity_Raw_pct | T2: Humidity_Clean_pct | U2: Humidity_Analysis_pct | V2: Humidity_Status | W2: Entry_Weight_Raw_g | X2: Entry_Weight_Positive_g | Y2: Weight_Status | Z2: Optical_Raw_ADC | AA2: Proximity_Raw_Flag | AB2: Optical_Detected | AC2: Weight_Detected | AD2: Person_Detected_Reported | AE2: Person_Detected_Final | AF2: Detection_Evidence | AG2: Flow_Raw | AH2: Flow_Clean_L_min | AI2: Flow_Status | AJ2: Pump_Expected | AK2: Humidifier_Expected | AL2: Fan_Reported | AM2: Fire_Alarm_Expected | AN2: Security_Alarm_Expected | AO2: Potential_Blockage_Flag | AP2: Calibration_Reference_g | AQ2: Calibration_Error_g | AR2: Calibration_Error_pct | AS2: Calibration_Point | AT2: Trial | AU2: Original_Unit | AV2: Original_Status | AW2: Processing_Method | AX2: Data_Quality_Score | AY2: Data_Quality_Grade | AZ2: README_Alignment | BA2: Notes
A3: REC-0001 | B3: Sensor Snapshot | C3: 5207 | D3: =IF(ISNUMBER(C3),C3/1000,"") -> 5.207 | E3: NORMAL | F3: 0 | G3: Integrated Monitoring | H3: MULTI_SENSOR | M3: =IF(L3="IDLE",0,IF(L3="FIRE_DETECTED",1,IF(L3="PUMPING",2,IF(L3="BLOCKED",3,IF(L3="HUMIDIFYING",4,IF(L3="STABLE",5,"")))))) | O3: 21.8 | P3: =IF(AND(ISNUMBER(O3),O3<>-1,O3>='02_Parameters'!$B$18,O3<='02_Parameters'!$B$19),O3,"") -> 21.8 | Q3: 21.8 | R3: =IF(B3<>"Sensor Snapshot","",IF(O3="","Missing",IF(O3=-1,"Sensor failure sentinel (-1)",IF(OR(O3<'02_Parameters'!$B$18,O3>'02_Parameters'!$B$19),"Out of accepted range","Valid")))) -> Valid | S3: 69.1 | T3: =IF(AND(ISNUMBER(S3),S3<>-1,S3>='02_Parameters'!$B$20,S3<='02_Parameters'!$B$21),S3,"") -> 69.1 | U3: 69.1 | V3: =IF(B3<>"Sensor Snapshot","",IF(S3="","Missing",IF(S3=-1,"Sensor failure sentinel (-1)",IF(OR(S3<'02_Parameters'!$B$20,S3>'02_Parameters'!$B$21),"Out of accepted range","Valid")))) -> Valid | W3: -0.0905 | X3: =IF(ISNUMBER(W3),ABS(W3),"") -> 0.0905 | Y3: =IF(B3="Calibration Trial","Calibration magnitude",IF(B3<>"Sensor Snapshot","",IF(W3="","Missing",IF(W3<0,"Sign corrected to positive","Valid")))) -> Sign corrected to positive | Z3: 863 | AB3: =IF(B3<>"Sensor Snapshot","",IF(ISNUMBER(AA3),--(AA3<>0),IF(ISNUMBER(Z3),--(Z3<'02_Parameters'!$B$15),""))) -> 0 | AC3: =IF(B3<>"Sensor Snapshot","",IF(ISNUMBER(X3),--(X3>='02_Parameters'!$B$16),"")) -> 0 | AD3: 0 | AE3: =IF(B3<>"Sensor Snapshot","",IF(AD3=1,1,IF(AND(AB3=1,AC3=1),1,0))) -> 0 | AF3: =IF(B3<>"Sensor Snapshot","",IF(AD3=1,"Logged dual-sensor event",IF(AE3=1,"Derived: optical AND weight",IF(OR(AB3=1,AC3=1),"Partial detection only","No detection")))) -> No detection | AG3: 0 | AH3: =IF(B3<>"Sensor Snapshot","",IF(ISNUMBER(AG3),IF(AG3<0,"",IF(AG3>10,AG3/'02_Parameters'!$B$17,AG3)),"")) -> 0 | AI3: =IF(B3<>"Sensor Snapshot","",IF(AG3="","Missing",IF(AG3<0,"Invalid negative flow",IF(AG3>10,"Normalized from high-scale log","Valid")))) -> Valid | AJ3: =IF(B3<>"Sensor Snapshot","",--(L3="PUMPING")) -> 0 | AK3: =IF(B3<>"Sensor Snapshot","",--(L3="HUMIDIFYING")) -> 0 | AM3: =IF(B3<>"Sensor Snapshot","",--(OR(L3="FIRE_DETECTED",L3="BLOCKED"))) -> 0 | AN3: =IF(B3<>"Sensor Snapshot","",--(N3>='02_Parameters'!$B$13)) -> 0 | AO3: =IF(B3<>"Sensor Snapshot","",--(AND(L3="PUMPING",ISNUMBER(AH3),AH3<='02_Parameters'!$B$10))) -> 0 | AQ3: =IF(B3="Calibration Trial",X3-AP3,"") | AR3: =IF(AND(B3="Calibration Trial",AP3<>0),AQ3/AP3*100,"") | AU3: mixed | AV3: snapshot | AW3: Load-cell sign corrected with absolute value | AX3: =IF(B3<>"Sensor Snapshot","",IF(P3<>"",20,0)+IF(T3<>"",20,0)+IF(X3<>"",20,0)+IF(AB3<>"",20,0)+IF(AH3<>"",20,0)) -> 100 | AY3: =IF(AX3="","",IF(AX3>=90,"A",IF(AX3>=75,"B",IF(AX3>=60,"C","D")))) -> A | AZ3: Corrected model: load cell treated only as entry-platform sensor | BA3: Grouped from five long-format sensor rows.
A4: REC-0002 | B4: System Event | C4: 5419 | D4: =IF(ISNUMBER(C4),C4/1000,"") -> 5.419 | E4: NORMAL | G4: Fire Protection | H4: FAN | I4: Fan ON | J4: fan on | M4: =IF(L4="IDLE",0,IF(L4="FIRE_DETECTED",1,IF(L4="PUMPING",2,IF(L4="BLOCKED",3,IF(L4="HUMIDIFYING",4,IF(L4="STABLE",5,"")))))) | P4: =IF(AND(ISNUMBER(O4),O4<>-1,O4>='02_Parameters'!$B$18,O4<='02_Parameters'!$B$19),O4,"") | R4: =IF(B4<>"Sensor Snapshot","",IF(O4="","Missing",IF(O4=-1,"Sensor failure sentinel (-1)",IF(OR(O4<'02_Parameters'!$B$18,O4>'02_Parameters'!$B$19),"Out of accepted range","Valid")))) | T4: =IF(AND(ISNUMBER(S4),S4<>-1,S4>='02_Parameters'!$B$20,S4<='02_Parameters'!$B$21),S4,"") | V4: =IF(B4<>"Sensor Snapshot","",IF(S4="","Missing",IF(S4=-1,"Sensor failure sentinel (-1)",IF(OR(S4<'02_Parameters'!$B$20,S4>'02_Parameters'!$B$21),"Out of accepted range","Valid")))) | X4: =IF(ISNUMBER(W4),ABS(W4),"") | Y4: =IF(B4="Calibration Trial","Calibration magnitude",IF(B4<>"Sensor Snapshot","",IF(W4="","Missing",IF(W4<0,"Sign corrected to positive","Valid")))) | AB4: =IF(B4<>"Sensor Snapshot","",IF(ISNUMBER(AA4),--(AA4<>0),IF(ISNUMBER(Z4),--(Z4<'02_Parameters'!$B$15),""))) | AC4: =IF(B4<>"Sensor Snapshot","",IF(ISNUMBER(X4),--(X4>='02_Parameters'!$B$16),"")) | AD4: 0 | AE4: =IF(B4<>"Sensor Snapshot","",IF(AD4=1,1,IF(AND(AB4=1,AC4=1),1,0))) | AF4: =IF(B4<>"Sensor Snapshot","",IF(AD4=1,"Logged dual-sensor event",IF(AE4=1,"Derived: optical AND weight",IF(OR(AB4=1,AC4=1),"Partial detection only","No detection")))) | AH4: =IF(B4<>"Sensor Snapshot","",IF(ISNUMBER(AG4),IF(AG4<0,"",IF(AG4>10,AG4/'02_Parameters'!$B$17,AG4)),"")) | AI4: =IF(B4<>"Sensor Snapshot","",IF(AG4="","Missing",IF(AG4<0,"Invalid negative flow",IF(AG4>10,"Normalized from high-scale log","Valid")))) | AJ4: =IF(B4<>"Sensor Snapshot","",--(L4="PUMPING")) | AK4: =IF(B4<>"Sensor Snapshot","",--(L4="HUMIDIFYING")) | AL4: 1 | AM4: =IF(B4<>"Sensor Snapshot","",--(OR(L4="FIRE_DETECTED",L4="BLOCKED"))) | AN4: =IF(B4<>"Sensor Snapshot","",--(N4>='02_Parameters'!$B$13)) | AO4: =IF(B4<>"Sensor Snapshot","",--(AND(L4="PUMPING",ISNUMBER(AH4),AH4<='02_Parameters'!$B$10))) | AQ4: =IF(B4="Calibration Trial",X4-AP4,"") | AR4: =IF(AND(B4="Calibration Trial",AP4<>0),AQ4/AP4*100,"") | AW4: Event standardized; original event preserved in raw-data sheet | AX4: =IF(B4<>"Sensor Snapshot","",IF(P4<>"",20,0)+IF(T4<>"",20,0)+IF(X4<>"",20,0)+IF(AB4<>"",20,0)+IF(AH4<>"",20,0)) | AY4: =IF(AX4="","",IF(AX4>=90,"A",IF(AX4>=75,"B",IF(AX4>=60,"C","D")))) | AZ4: Consistent with corrected README sequence
A5: REC-0003 | B5: System Event | C5: 8001 | D5: =IF(ISNUMBER(C5),C5/1000,"") -> 8.001 | E5: NORMAL | G5: Entry Security | H5: SECURITY | I5: Legacy Proximity Trigger | J5: proximity detected | M5: =IF(L5="IDLE",0,IF(L5="FIRE_DETECTED",1,IF(L5="PUMPING",2,IF(L5="BLOCKED",3,IF(L5="HUMIDIFYING",4,IF(L5="STABLE",5,"")))))) | P5: =IF(AND(ISNUMBER(O5),O5<>-1,O5>='02_Parameters'!$B$18,O5<='02_Parameters'!$B$19),O5,"") | R5: =IF(B5<>"Sensor Snapshot","",IF(O5="","Missing",IF(O5=-1,"Sensor failure sentinel (-1)",IF(OR(O5<'02_Parameters'!$B$18,O5>'02_Parameters'!$B$19),"Out of accepted range","Valid")))) | T5: =IF(AND(ISNUMBER(S5),S5<>-1,S5>='02_Parameters'!$B$20,S5<='02_Parameters'!$B$21),S5,"") | V5: =IF(B5<>"Sensor Snapshot","",IF(S5="","Missing",IF(S5=-1,"Sensor failure sentinel (-1)",IF(OR(S5<'02_Parameters'!$B$20,S5>'02_Parameters'!$B$21),"Out of accepted range","Valid")))) | X5: =IF(ISNUMBER(W5),ABS(W5),"") | Y5: =IF(B5="Calibration Trial","Calibration magnitude",IF(B5<>"Sensor Snapshot","",IF(W5="","Missing",IF(W5<0,"Sign corrected to positive","Valid")))) | AB5: =IF(B5<>"Sensor Snapshot","",IF(ISNUMBER(AA5),--(AA5<>0),IF(ISNUMBER(Z5),--(Z5<'02_Parameters'!$B$15),""))) | AC5: =IF(B5<>"Sensor Snapshot","",IF(ISNUMBER(X5),--(X5>='02_Parameters'!$B$16),"")) | AD5: 0 | AE5: =IF(B5<>"Sensor Snapshot","",IF(AD5=1,1,IF(AND(AB5=1,AC5=1),1,0))) | AF5: =IF(B5<>"Sensor Snapshot","",IF(AD5=1,"Logged dual-sensor event",IF(AE5=1,"Derived: optical AND weight",IF(OR(AB5=1,AC5=1),"Partial detection only","No detection")))) | AH5: =IF(B5<>"Sensor Snapshot","",IF(ISNUMBER(AG5),IF(AG5<0,"",IF(AG5>10,AG5/'02_Parameters'!$B$17,AG5)),"")) | AI5: =IF(B5<>"Sensor Snapshot","",IF(AG5="","Missing",IF(AG5<0,"Invalid negative flow",IF(AG5>10,"Normalized from high-scale log","Valid")))) | AJ5: =IF(B5<>"Sensor Snapshot","",--(L5="PUMPING")) | AK5: =IF(B5<>"Sensor Snapshot","",--(L5="HUMIDIFYING")) | AM5: =IF(B5<>"Sensor Snapshot","",--(OR(L5="FIRE_DETECTED",L5="BLOCKED"))) | AN5: =IF(B5<>"Sensor Snapshot","",--(N5>='02_Parameters'!$B$13)) | AO5: =IF(B5<>"Sensor Snapshot","",--(AND(L5="PUMPING",ISNUMBER(AH5),AH5<='02_Parameters'!$B$10))) | AQ5: =IF(B5="Calibration Trial",X5-AP5,"") | AR5: =IF(AND(B5="Calibration Trial",AP5<>0),AQ5/AP5*100,"") | AW5: Event standardized; original event preserved in raw-data sheet | AX5: =IF(B5<>"Sensor Snapshot","",IF(P5<>"",20,0)+IF(T5<>"",20,0)+IF(X5<>"",20,0)+IF(AB5<>"",20,0)+IF(AH5<>"",20,0)) | AY5: =IF(AX5="","",IF(AX5>=90,"A",IF(AX5>=75,"B",IF(AX5>=60,"C","D")))) | AZ5: Legacy optical-only label; corrected README requires optical AND load-cell confirmation
A6: REC-0004 | B6: System Event | C6: 8513 | D6: =IF(ISNUMBER(C6),C6/1000,"") -> 8.513 | E6: NORMAL | G6: Entry Security | H6: SECURITY | I6: PIN Entry Started | J6: password started | M6: =IF(L6="IDLE",0,IF(L6="FIRE_DETECTED",1,IF(L6="PUMPING",2,IF(L6="BLOCKED",3,IF(L6="HUMIDIFYING",4,IF(L6="STABLE",5,"")))))) | P6: =IF(AND(ISNUMBER(O6),O6<>-1,O6>='02_Parameters'!$B$18,O6<='02_Parameters'!$B$19),O6,"") | R6: =IF(B6<>"Sensor Snapshot","",IF(O6="","Missing",IF(O6=-1,"Sensor failure sentinel (-1)",IF(OR(O6<'02_Parameters'!$B$18,O6>'02_Parameters'!$B$19),"Out of accepted range","Valid")))) | T6: =IF(AND(ISNUMBER(S6),S6<>-1,S6>='02_Parameters'!$B$20,S6<='02_Parameters'!$B$21),S6,"") | V6: =IF(B6<>"Sensor Snapshot","",IF(S6="","Missing",IF(S6=-1,"Sensor failure sentinel (-1)",IF(OR(S6<'02_Parameters'!$B$20,S6>'02_Parameters'!$B$21),"Out of accepted range","Valid")))) | X6: =IF(ISNUMBER(W6),ABS(W6),"") | Y6: =IF(B6="Calibration Trial","Calibration magnitude",IF(B6<>"Sensor Snapshot","",IF(W6="","Missing",IF(W6<0,"Sign corrected to positive","Valid")))) | AB6: =IF(B6<>"Sensor Snapshot","",IF(ISNUMBER(AA6),--(AA6<>0),IF(ISNUMBER(Z6),--(Z6<'02_Parameters'!$B$15),""))) | AC6: =IF(B6<>"Sensor Snapshot","",IF(ISNUMBER(X6),--(X6>='02_Parameters'!$B$16),"")) | AD6: 0 | AE6: =IF(B6<>"Sensor Snapshot","",IF(AD6=1,1,IF(AND(AB6=1,AC6=1),1,0))) | AF6: =IF(B6<>"Sensor Snapshot","",IF(AD6=1,"Logged dual-sensor event",IF(AE6=1,"Derived: optical AND weight",IF(OR(AB6=1,AC6=1),"Partial detection only","No detection")))) | AH6: =IF(B6<>"Sensor Snapshot","",IF(ISNUMBER(AG6),IF(AG6<0,"",IF(AG6>10,AG6/'02_Parameters'!$B$17,AG6)),"")) | AI6: =IF(B6<>"Sensor Snapshot","",IF(AG6="","Missing",IF(AG6<0,"Invalid negative flow",IF(AG6>10,"Normalized from high-scale log","Valid")))) | AJ6: =IF(B6<>"Sensor Snapshot","",--(L6="PUMPING")) | AK6: =IF(B6<>"Sensor Snapshot","",--(L6="HUMIDIFYING")) | AM6: =IF(B6<>"Sensor Snapshot","",--(OR(L6="FIRE_DETECTED",L6="BLOCKED"))) | AN6: =IF(B6<>"Sensor Snapshot","",--(N6>='02_Parameters'!$B$13)) | AO6: =IF(B6<>"Sensor Snapshot","",--(AND(L6="PUMPING",ISNUMBER(AH6),AH6<='02_Parameters'!$B$10))) | AQ6: =IF(B6="Calibration Trial",X6-AP6,"") | AR6: =IF(AND(B6="Calibration Trial",AP6<>0),AQ6/AP6*100,"") | AW6: Event standardized; original event preserved in raw-data sheet | AX6: =IF(B6<>"Sensor Snapshot","",IF(P6<>"",20,0)+IF(T6<>"",20,0)+IF(X6<>"",20,0)+IF(AB6<>"",20,0)+IF(AH6<>"",20,0)) | AY6: =IF(AX6="","",IF(AX6>=90,"A",IF(AX6>=75,"B",IF(AX6>=60,"C","D")))) | AZ6: Consistent with corrected README sequence
A7: REC-0005 | B7: Sensor Snapshot | C7: 23639 | D7: =IF(ISNUMBER(C7),C7/1000,"") -> 23.639 | E7: NORMAL | F7: 1 | G7: Integrated Monitoring | H7: MULTI_SENSOR | M7: =IF(L7="IDLE",0,IF(L7="FIRE_DETECTED",1,IF(L7="PUMPING",2,IF(L7="BLOCKED",3,IF(L7="HUMIDIFYING",4,IF(L7="STABLE",5,"")))))) | O7: 21.9 | P7: =IF(AND(ISNUMBER(O7),O7<>-1,O7>='02_Parameters'!$B$18,O7<='02_Parameters'!$B$19),O7,"") -> 21.9 | Q7: 21.9 | R7: =IF(B7<>"Sensor Snapshot","",IF(O7="","Missing",IF(O7=-1,"Sensor failure sentinel (-1)",IF(OR(O7<'02_Parameters'!$B$18,O7>'02_Parameters'!$B$19),"Out of accepted range","Valid")))) -> Valid | S7: 69.4 | T7: =IF(AND(ISNUMBER(S7),S7<>-1,S7>='02_Parameters'!$B$20,S7<='02_Parameters'!$B$21),S7,"") -> 69.4 | U7: 69.4 | V7: =IF(B7<>"Sensor Snapshot","",IF(S7="","Missing",IF(S7=-1,"Sensor failure sentinel (-1)",IF(OR(S7<'02_Parameters'!$B$20,S7>'02_Parameters'!$B$21),"Out of accepted range","Valid")))) -> Valid | W7: 10.1952 | X7: =IF(ISNUMBER(W7),ABS(W7),"") -> 10.1952 | Y7: =IF(B7="Calibration Trial","Calibration magnitude",IF(B7<>"Sensor Snapshot","",IF(W7="","Missing",IF(W7<0,"Sign corrected to positive","Valid")))) -> Valid | Z7: 845 | AB7: =IF(B7<>"Sensor Snapshot","",IF(ISNUMBER(AA7),--(AA7<>0),IF(ISNUMBER(Z7),--(Z7<'02_Parameters'!$B$15),""))) -> 0 | AC7: =IF(B7<>"Sensor Snapshot","",IF(ISNUMBER(X7),--(X7>='02_Parameters'!$B$16),"")) -> 1 | AD7: 0 | AE7: =IF(B7<>"Sensor Snapshot","",IF(AD7=1,1,IF(AND(AB7=1,AC7=1),1,0))) -> 0 | AF7: =IF(B7<>"Sensor Snapshot","",IF(AD7=1,"Logged dual-sensor event",IF(AE7=1,"Derived: optical AND weight",IF(OR(AB7=1,AC7=1),"Partial detection only","No detection")))) -> Partial detection only | AG7: 0 | AH7: =IF(B7<>"Sensor Snapshot","",IF(ISNUMBER(AG7),IF(AG7<0,"",IF(AG7>10,AG7/'02_Parameters'!$B$17,AG7)),"")) -> 0 | AI7: =IF(B7<>"Sensor Snapshot","",IF(AG7="","Missing",IF(AG7<0,"Invalid negative flow",IF(AG7>10,"Normalized from high-scale log","Valid")))) -> Valid | AJ7: =IF(B7<>"Sensor Snapshot","",--(L7="PUMPING")) -> 0 | AK7: =IF(B7<>"Sensor Snapshot","",--(L7="HUMIDIFYING")) -> 0 | AM7: =IF(B7<>"Sensor Snapshot","",--(OR(L7="FIRE_DETECTED",L7="BLOCKED"))) -> 0 | AN7: =IF(B7<>"Sensor Snapshot","",--(N7>='02_Parameters'!$B$13)) -> 0 | AO7: =IF(B7<>"Sensor Snapshot","",--(AND(L7="PUMPING",ISNUMBER(AH7),AH7<='02_Parameters'!$B$10))) -> 0 | AQ7: =IF(B7="Calibration Trial",X7-AP7,"") | AR7: =IF(AND(B7="Calibration Trial",AP7<>0),AQ7/AP7*100,"") | AU7: mixed | AV7: snapshot | AW7: Raw values retained; derived fields calculated transparently | AX7: =IF(B7<>"Sensor Snapshot","",IF(P7<>"",20,0)+IF(T7<>"",20,0)+IF(X7<>"",20,0)+IF(AB7<>"",20,0)+IF(AH7<>"",20,0)) -> 100 | AY7: =IF(AX7="","",IF(AX7>=90,"A",IF(AX7>=75,"B",IF(AX7>=60,"C","D")))) -> A | AZ7: Corrected model: load cell treated only as entry-platform sensor | BA7: Grouped from five long-format sensor rows.
A8: REC-0006 | B8: System Event | C8: 23856 | D8: =IF(ISNUMBER(C8),C8/1000,"") -> 23.856 | E8: NORMAL | G8: Fire Protection | H8: FAN | I8: Fan OFF | J8: fan off | M8: =IF(L8="IDLE",0,IF(L8="FIRE_DETECTED",1,IF(L8="PUMPING",2,IF(L8="BLOCKED",3,IF(L8="HUMIDIFYING",4,IF(L8="STABLE",5,"")))))) | P8: =IF(AND(ISNUMBER(O8),O8<>-1,O8>='02_Parameters'!$B$18,O8<='02_Parameters'!$B$19),O8,"") | R8: =IF(B8<>"Sensor Snapshot","",IF(O8="","Missing",IF(O8=-1,"Sensor failure sentinel (-1)",IF(OR(O8<'02_Parameters'!$B$18,O8>'02_Parameters'!$B$19),"Out of accepted range","Valid")))) | T8: =IF(AND(ISNUMBER(S8),S8<>-1,S8>='02_Parameters'!$B$20,S8<='02_Parameters'!$B$21),S8,"") | V8: =IF(B8<>"Sensor Snapshot","",IF(S8="","Missing",IF(S8=-1,"Sensor failure sentinel (-1)",IF(OR(S8<'02_Parameters'!$B$20,S8>'02_Parameters'!$B$21),"Out of accepted range","Valid")))) | X8: =IF(ISNUMBER(W8),ABS(W8),"") | Y8: =IF(B8="Calibration Trial","Calibration magnitude",IF(B8<>"Sensor Snapshot","",IF(W8="","Missing",IF(W8<0,"Sign corrected to positive","Valid")))) | AB8: =IF(B8<>"Sensor Snapshot","",IF(ISNUMBER(AA8),--(AA8<>0),IF(ISNUMBER(Z8),--(Z8<'02_Parameters'!$B$15),""))) | AC8: =IF(B8<>"Sensor Snapshot","",IF(ISNUMBER(X8),--(X8>='02_Parameters'!$B$16),"")) | AD8: 0 | AE8: =IF(B8<>"Sensor Snapshot","",IF(AD8=1,1,IF(AND(AB8=1,AC8=1),1,0))) | AF8: =IF(B8<>"Sensor Snapshot","",IF(AD8=1,"Logged dual-sensor event",IF(AE8=1,"Derived: optical AND weight",IF(OR(AB8=1,AC8=1),"Partial detection only","No detection")))) | AH8: =IF(B8<>"Sensor Snapshot","",IF(ISNUMBER(AG8),IF(AG8<0,"",IF(AG8>10,AG8/'02_Parameters'!$B$17,AG8)),"")) | AI8: =IF(B8<>"Sensor Snapshot","",IF(AG8="","Missing",IF(AG8<0,"Invalid negative flow",IF(AG8>10,"Normalized from high-scale log","Valid")))) | AJ8: =IF(B8<>"Sensor Snapshot","",--(L8="PUMPING")) | AK8: =IF(B8<>"Sensor Snapshot","",--(L8="HUMIDIFYING")) | AL8: 0 | AM8: =IF(B8<>"Sensor Snapshot","",--(OR(L8="FIRE_DETECTED",L8="BLOCKED"))) | AN8: =IF(B8<>"Sensor Snapshot","",--(N8>='02_Parameters'!$B$13)) | AO8: =IF(B8<>"Sensor Snapshot","",--(AND(L8="PUMPING",ISNUMBER(AH8),AH8<='02_Parameters'!$B$10))) | AQ8: =IF(B8="Calibration Trial",X8-AP8,"") | AR8: =IF(AND(B8="Calibration Trial",AP8<>0),AQ8/AP8*100,"") | AW8: Event standardized; original event preserved in raw-data sheet | AX8: =IF(B8<>"Sensor Snapshot","",IF(P8<>"",20,0)+IF(T8<>"",20,0)+IF(X8<>"",20,0)+IF(AB8<>"",20,0)+IF(AH8<>"",20,0)) | AY8: =IF(AX8="","",IF(AX8>=90,"A",IF(AX8>=75,"B",IF(AX8>=60,"C","D")))) | AZ8: Consistent with corrected README sequence
A9: REC-0007 | B9: Calibration Trial | C9: 23897 | D9: =IF(ISNUMBER(C9),C9/1000,"") -> 23.897 | E9: CALIB | F9: 0 | G9: Entry Security | H9: LOADCELL | I9: Load-Cell Calibration | J9: Known reference weight test on entry platform | M9: =IF(L9="IDLE",0,IF(L9="FIRE_DETECTED",1,IF(L9="PUMPING",2,IF(L9="BLOCKED",3,IF(L9="HUMIDIFYING",4,IF(L9="STABLE",5,"")))))) | P9: =IF(AND(ISNUMBER(O9),O9<>-1,O9>='02_Parameters'!$B$18,O9<='02_Parameters'!$B$19),O9,"") | R9: =IF(B9<>"Sensor Snapshot","",IF(O9="","Missing",IF(O9=-1,"Sensor failure sentinel (-1)",IF(OR(O9<'02_Parameters'!$B$18,O9>'02_Parameters'!$B$19),"Out of accepted range","Valid")))) | T9: =IF(AND(ISNUMBER(S9),S9<>-1,S9>='02_Parameters'!$B$20,S9<='02_Parameters'!$B$21),S9,"") | V9: =IF(B9<>"Sensor Snapshot","",IF(S9="","Missing",IF(S9=-1,"Sensor failure sentinel (-1)",IF(OR(S9<'02_Parameters'!$B$20,S9>'02_Parameters'!$B$21),"Out of accepted range","Valid")))) | W9: 33.2976 | X9: =IF(ISNUMBER(W9),ABS(W9),"") -> 33.2976 | Y9: =IF(B9="Calibration Trial","Calibration magnitude",IF(B9<>"Sensor Snapshot","",IF(W9="","Missing",IF(W9<0,"Sign corrected to positive","Valid")))) -> Calibration magnitude | AB9: =IF(B9<>"Sensor Snapshot","",IF(ISNUMBER(AA9),--(AA9<>0),IF(ISNUMBER(Z9),--(Z9<'02_Parameters'!$B$15),""))) | AC9: =IF(B9<>"Sensor Snapshot","",IF(ISNUMBER(X9),--(X9>='02_Parameters'!$B$16),"")) | AD9: 0 | AE9: =IF(B9<>"Sensor Snapshot","",IF(AD9=1,1,IF(AND(AB9=1,AC9=1),1,0))) | AF9: =IF(B9<>"Sensor Snapshot","",IF(AD9=1,"Logged dual-sensor event",IF(AE9=1,"Derived: optical AND weight",IF(OR(AB9=1,AC9=1),"Partial detection only","No detection")))) | AH9: =IF(B9<>"Sensor Snapshot","",IF(ISNUMBER(AG9),IF(AG9<0,"",IF(AG9>10,AG9/'02_Parameters'!$B$17,AG9)),"")) | AI9: =IF(B9<>"Sensor Snapshot","",IF(AG9="","Missing",IF(AG9<0,"Invalid negative flow",IF(AG9>10,"Normalized from high-scale log","Valid")))) | AJ9: =IF(B9<>"Sensor Snapshot","",--(L9="PUMPING")) | AK9: =IF(B9<>"Sensor Snapshot","",--(L9="HUMIDIFYING")) | AM9: =IF(B9<>"Sensor Snapshot","",--(OR(L9="FIRE_DETECTED",L9="BLOCKED"))) | AN9: =IF(B9<>"Sensor Snapshot","",--(N9>='02_Parameters'!$B$13)) | AO9: =IF(B9<>"Sensor Snapshot","",--(AND(L9="PUMPING",ISNUMBER(AH9),AH9<='02_Parameters'!$B$10))) | AP9: 500 | AQ9: =IF(B9="Calibration Trial",X9-AP9,"") -> -466.7024 | AR9: =IF(AND(B9="Calibration Trial",AP9<>0),AQ9/AP9*100,"") -> -93.34048 | AS9: 1 | AT9: 1 | AU9: g | AV9: ok | AW9: Signed reading preserved; positive magnitude used for calibration analysis | AX9: =IF(B9<>"Sensor Snapshot","",IF(P9<>"",20,0)+IF(T9<>"",20,0)+IF(X9<>"",20,0)+IF(AB9<>"",20,0)+IF(AH9<>"",20,0)) | AY9: =IF(AX9="","",IF(AX9>=90,"A",IF(AX9>=75,"B",IF(AX9>=60,"C","D")))) | AZ9: Compliant: load cell calibrated only for entry-platform presence detection | BA9: Original error columns are retained in the raw sheet; recalculated error uses positive magnitude.
A10: REC-0008 | B10: Calibration Trial | C10: 24279 | D10: =IF(ISNUMBER(C10),C10/1000,"") -> 24.279 | E10: CALIB | F10: 1 | G10: Entry Security | H10: LOADCELL | I10: Load-Cell Calibration | J10: Known reference weight test on entry platform | M10: =IF(L10="IDLE",0,IF(L10="FIRE_DETECTED",1,IF(L10="PUMPING",2,IF(L10="BLOCKED",3,IF(L10="HUMIDIFYING",4,IF(L10="STABLE",5,"")))))) | P10: =IF(AND(ISNUMBER(O10),O10<>-1,O10>='02_Parameters'!$B$18,O10<='02_Parameters'!$B$19),O10,"") | R10: =IF(B10<>"Sensor Snapshot","",IF(O10="","Missing",IF(O10=-1,"Sensor failure sentinel (-1)",IF(OR(O10<'02_Parameters'!$B$18,O10>'02_Parameters'!$B$19),"Out of accepted range","Valid")))) | T10: =IF(AND(ISNUMBER(S10),S10<>-1,S10>='02_Parameters'!$B$20,S10<='02_Parameters'!$B$21),S10,"") | V10: =IF(B10<>"Sensor Snapshot","",IF(S10="","Missing",IF(S10=-1,"Sensor failure sentinel (-1)",IF(OR(S10<'02_Parameters'!$B$20,S10>'02_Parameters'!$B$21),"Out of accepted range","Valid")))) | W10: 23.15 | X10: =IF(ISNUMBER(W10),ABS(W10),"") -> 23.15 | Y10: =IF(B10="Calibration Trial","Calibration magnitude",IF(B10<>"Sensor Snapshot","",IF(W10="","Missing",IF(W10<0,"Sign corrected to positive","Valid")))) -> Calibration magnitude | AB10: =IF(B10<>"Sensor Snapshot","",IF(ISNUMBER(AA10),--(AA10<>0),IF(ISNUMBER(Z10),--(Z10<'02_Parameters'!$B$15),""))) | AC10: =IF(B10<>"Sensor Snapshot","",IF(ISNUMBER(X10),--(X10>='02_Parameters'!$B$16),"")) | AD10: 0 | AE10: =IF(B10<>"Sensor Snapshot","",IF(AD10=1,1,IF(AND(AB10=1,AC10=1),1,0))) | AF10: =IF(B10<>"Sensor Snapshot","",IF(AD10=1,"Logged dual-sensor event",IF(AE10=1,"Derived: optical AND weight",IF(OR(AB10=1,AC10=1),"Partial detection only","No detection")))) | AH10: =IF(B10<>"Sensor Snapshot","",IF(ISNUMBER(AG10),IF(AG10<0,"",IF(AG10>10,AG10/'02_Parameters'!$B$17,AG10)),"")) | AI10: =IF(B10<>"Sensor Snapshot","",IF(AG10="","Missing",IF(AG10<0,"Invalid negative flow",IF(AG10>10,"Normalized from high-scale log","Valid")))) | AJ10: =IF(B10<>"Sensor Snapshot","",--(L10="PUMPING")) | AK10: =IF(B10<>"Sensor Snapshot","",--(L10="HUMIDIFYING")) | AM10: =IF(B10<>"Sensor Snapshot","",--(OR(L10="FIRE_DETECTED",L10="BLOCKED"))) | AN10: =IF(B10<>"Sensor Snapshot","",--(N10>='02_Parameters'!$B$13)) | AO10: =IF(B10<>"Sensor Snapshot","",--(AND(L10="PUMPING",ISNUMBER(AH10),AH10<='02_Parameters'!$B$10))) | AP10: 500 | AQ10: =IF(B10="Calibration Trial",X10-AP10,"") -> -476.85 | AR10: =IF(AND(B10="Calibration Trial",AP10<>0),AQ10/AP10*100,"") -> -95.37 | AS10: 1 | AT10: 2 | AU10: g | AV10: ok | AW10: Signed reading preserved; positive magnitude used for calibration analysis | AX10: =IF(B10<>"Sensor Snapshot","",IF(P10<>"",20,0)+IF(T10<>"",20,0)+IF(X10<>"",20,0)+IF(AB10<>"",20,0)+IF(AH10<>"",20,0)) | AY10: =IF(AX10="","",IF(AX10>=90,"A",IF(AX10>=75,"B",IF(AX10>=60,"C","D")))) | AZ10: Compliant: load cell calibrated only for entry-platform presence detection | BA10: Original error columns are retained in the raw sheet; recalculated error uses positive magnitude.
A11: REC-0009 | B11: Calibration Trial | C11: 24594 | D11: =IF(ISNUMBER(C11),C11/1000,"") -> 24.594 | E11: CALIB | F11: 2 | G11: Entry Security | H11: LOADCELL | I11: Load-Cell Calibration | J11: Known reference weight test on entry platform | M11: =IF(L11="IDLE",0,IF(L11="FIRE_DETECTED",1,IF(L11="PUMPING",2,IF(L11="BLOCKED",3,IF(L11="HUMIDIFYING",4,IF(L11="STABLE",5,"")))))) | P11: =IF(AND(ISNUMBER(O11),O11<>-1,O11>='02_Parameters'!$B$18,O11<='02_Parameters'!$B$19),O11,"") | R11: =IF(B11<>"Sensor Snapshot","",IF(O11="","Missing",IF(O11=-1,"Sensor failure sentinel (-1)",IF(OR(O11<'02_Parameters'!$B$18,O11>'02_Parameters'!$B$19),"Out of accepted range","Valid")))) | T11: =IF(AND(ISNUMBER(S11),S11<>-1,S11>='02_Parameters'!$B$20,S11<='02_Parameters'!$B$21),S11,"") | V11: =IF(B11<>"Sensor Snapshot","",IF(S11="","Missing",IF(S11=-1,"Sensor failure sentinel (-1)",IF(OR(S11<'02_Parameters'!$B$20,S11>'02_Parameters'!$B$21),"Out of accepted range","Valid")))) | W11: 7.6905 | X11: =IF(ISNUMBER(W11),ABS(W11),"") -> 7.6905 | Y11: =IF(B11="Calibration Trial","Calibration magnitude",IF(B11<>"Sensor Snapshot","",IF(W11="","Missing",IF(W11<0,"Sign corrected to positive","Valid")))) -> Calibration magnitude | AB11: =IF(B11<>"Sensor Snapshot","",IF(ISNUMBER(AA11),--(AA11<>0),IF(ISNUMBER(Z11),--(Z11<'02_Parameters'!$B$15),""))) | AC11: =IF(B11<>"Sensor Snapshot","",IF(ISNUMBER(X11),--(X11>='02_Parameters'!$B$16),"")) | AD11: 0 | AE11: =IF(B11<>"Sensor Snapshot","",IF(AD11=1,1,IF(AND(AB11=1,AC11=1),1,0))) | AF11: =IF(B11<>"Sensor Snapshot","",IF(AD11=1,"Logged dual-sensor event",IF(AE11=1,"Derived: optical AND weight",IF(OR(AB11=1,AC11=1),"Partial detection only","No detection")))) | AH11: =IF(B11<>"Sensor Snapshot","",IF(ISNUMBER(AG11),IF(AG11<0,"",IF(AG11>10,AG11/'02_Parameters'!$B$17,AG11)),"")) | AI11: =IF(B11<>"Sensor Snapshot","",IF(AG11="","Missing",IF(AG11<0,"Invalid negative flow",IF(AG11>10,"Normalized from high-scale log","Valid")))) | AJ11: =IF(B11<>"Sensor Snapshot","",--(L11="PUMPING")) | AK11: =IF(B11<>"Sensor Snapshot","",--(L11="HUMIDIFYING")) | AM11: =IF(B11<>"Sensor Snapshot","",--(OR(L11="FIRE_DETECTED",L11="BLOCKED"))) | AN11: =IF(B11<>"Sensor Snapshot","",--(N11>='02_Parameters'!$B$13)) | AO11: =IF(B11<>"Sensor Snapshot","",--(AND(L11="PUMPING",ISNUMBER(AH11),AH11<='02_Parameters'!$B$10))) | AP11: 500 | AQ11: =IF(B11="Calibration Trial",X11-AP11,"") -> -492.3095 | AR11: =IF(AND(B11="Calibration Trial",AP11<>0),AQ11/AP11*100,"") -> -98.4619 | AS11: 1 | AT11: 3 | AU11: g | AV11: ok | AW11: Signed reading preserved; positive magnitude used for calibration analysis | AX11: =IF(B11<>"Sensor Snapshot","",IF(P11<>"",20,0)+IF(T11<>"",20,0)+IF(X11<>"",20,0)+IF(AB11<>"",20,0)+IF(AH11<>"",20,0)) | AY11: =IF(AX11="","",IF(AX11>=90,"A",IF(AX11>=75,"B",IF(AX11>=60,"C","D")))) | AZ11: Compliant: load cell calibrated only for entry-platform presence detection | BA11: Original error columns are retained in the raw sheet; recalculated error uses positive magnitude.
A12: REC-0010 | B12: Calibration Trial | C12: 24907 | D12: =IF(ISNUMBER(C12),C12/1000,"") -> 24.907 | E12: CALIB | F12: 3 | G12: Entry Security | H12: LOADCELL | I12: Load-Cell Calibration | J12: Known reference weight test on entry platform | M12: =IF(L12="IDLE",0,IF(L12="FIRE_DETECTED",1,IF(L12="PUMPING",2,IF(L12="BLOCKED",3,IF(L12="HUMIDIFYING",4,IF(L12="STABLE",5,"")))))) | P12: =IF(AND(ISNUMBER(O12),O12<>-1,O12>='02_Parameters'!$B$18,O12<='02_Parameters'!$B$19),O12,"") | R12: =IF(B12<>"Sensor Snapshot","",IF(O12="","Missing",IF(O12=-1,"Sensor failure sentinel (-1)",IF(OR(O12<'02_Parameters'!$B$18,O12>'02_Parameters'!$B$19),"Out of accepted range","Valid")))) | T12: =IF(AND(ISNUMBER(S12),S12<>-1,S12>='02_Parameters'!$B$20,S12<='02_Parameters'!$B$21),S12,"") | V12: =IF(B12<>"Sensor Snapshot","",IF(S12="","Missing",IF(S12=-1,"Sensor failure sentinel (-1)",IF(OR(S12<'02_Parameters'!$B$20,S12>'02_Parameters'!$B$21),"Out of accepted range","Valid")))) | W12: 14.7905 | X12: =IF(ISNUMBER(W12),ABS(W12),"") -> 14.7905 | Y12: =IF(B12="Calibration Trial","Calibration magnitude",IF(B12<>"Sensor Snapshot","",IF(W12="","Missing",IF(W12<0,"Sign corrected to positive","Valid")))) -> Calibration magnitude | AB12: =IF(B12<>"Sensor Snapshot","",IF(ISNUMBER(AA12),--(AA12<>0),IF(ISNUMBER(Z12),--(Z12<'02_Parameters'!$B$15),""))) | AC12: =IF(B12<>"Sensor Snapshot","",IF(ISNUMBER(X12),--(X12>='02_Parameters'!$B$16),"")) | AD12: 0 | AE12: =IF(B12<>"Sensor Snapshot","",IF(AD12=1,1,IF(AND(AB12=1,AC12=1),1,0))) | AF12: =IF(B12<>"Sensor Snapshot","",IF(AD12=1,"Logged dual-sensor event",IF(AE12=1,"Derived: optical AND weight",IF(OR(AB12=1,AC12=1),"Partial detection only","No detection")))) | AH12: =IF(B12<>"Sensor Snapshot","",IF(ISNUMBER(AG12),IF(AG12<0,"",IF(AG12>10,AG12/'02_Parameters'!$B$17,AG12)),"")) | AI12: =IF(B12<>"Sensor Snapshot","",IF(AG12="","Missing",IF(AG12<0,"Invalid negative flow",IF(AG12>10,"Normalized from high-scale log","Valid")))) | AJ12: =IF(B12<>"Sensor Snapshot","",--(L12="PUMPING")) | AK12: =IF(B12<>"Sensor Snapshot","",--(L12="HUMIDIFYING")) | AM12: =IF(B12<>"Sensor Snapshot","",--(OR(L12="FIRE_DETECTED",L12="BLOCKED"))) | AN12: =IF(B12<>"Sensor Snapshot","",--(N12>='02_Parameters'!$B$13)) | AO12: =IF(B12<>"Sensor Snapshot","",--(AND(L12="PUMPING",ISNUMBER(AH12),AH12<='02_Parameters'!$B$10))) | AP12: 500 | AQ12: =IF(B12="Calibration Trial",X12-AP12,"") -> -485.2095 | AR12: =IF(AND(B12="Calibration Trial",AP12<>0),AQ12/AP12*100,"") -> -97.0419 | AS12: 1 | AT12: 4 | AU12: g | AV12: ok | AW12: Signed reading preserved; positive magnitude used for calibration analysis | AX12: =IF(B12<>"Sensor Snapshot","",IF(P12<>"",20,0)+IF(T12<>"",20,0)+IF(X12<>"",20,0)+IF(AB12<>"",20,0)+IF(AH12<>"",20,0)) | AY12: =IF(AX12="","",IF(AX12>=90,"A",IF(AX12>=75,"B",IF(AX12>=60,"C","D")))) | AZ12: Compliant: load cell calibrated only for entry-platform presence detection | BA12: Original error columns are retained in the raw sheet; recalculated error uses positive magnitude.
A13: REC-0011 | B13: Calibration Trial | C13: 25223 | D13: =IF(ISNUMBER(C13),C13/1000,"") -> 25.223 | E13: CALIB | F13: 4 | G13: Entry Security | H13: LOADCELL | I13: Load-Cell Calibration | J13: Known reference weight test on entry platform | M13: =IF(L13="IDLE",0,IF(L13="FIRE_DETECTED",1,IF(L13="PUMPING",2,IF(L13="BLOCKED",3,IF(L13="HUMIDIFYING",4,IF(L13="STABLE",5,"")))))) | P13: =IF(AND(ISNUMBER(O13),O13<>-1,O13>='02_Parameters'!$B$18,O13<='02_Parameters'!$B$19),O13,"") | R13: =IF(B13<>"Sensor Snapshot","",IF(O13="","Missing",IF(O13=-1,"Sensor failure sentinel (-1)",IF(OR(O13<'02_Parameters'!$B$18,O13>'02_Parameters'!$B$19),"Out of accepted range","Valid")))) | T13: =IF(AND(ISNUMBER(S13),S13<>-1,S13>='02_Parameters'!$B$20,S13<='02_Parameters'!$B$21),S13,"") | V13: =IF(B13<>"Sensor Snapshot","",IF(S13="","Missing",IF(S13=-1,"Sensor failure sentinel (-1)",IF(OR(S13<'02_Parameters'!$B$20,S13>'02_Parameters'!$B$21),"Out of accepted range","Valid")))) | W13: 6.7524 | X13: =IF(ISNUMBER(W13),ABS(W13),"") -> 6.7524 | Y13: =IF(B13="Calibration Trial","Calibration magnitude",IF(B13<>"Sensor Snapshot","",IF(W13="","Missing",IF(W13<0,"Sign corrected to positive","Valid")))) -> Calibration magnitude | AB13: =IF(B13<>"Sensor Snapshot","",IF(ISNUMBER(AA13),--(AA13<>0),IF(ISNUMBER(Z13),--(Z13<'02_Parameters'!$B$15),""))) | AC13: =IF(B13<>"Sensor Snapshot","",IF(ISNUMBER(X13),--(X13>='02_Parameters'!$B$16),"")) | AD13: 0 | AE13: =IF(B13<>"Sensor Snapshot","",IF(AD13=1,1,IF(AND(AB13=1,AC13=1),1,0))) | AF13: =IF(B13<>"Sensor Snapshot","",IF(AD13=1,"Logged dual-sensor event",IF(AE13=1,"Derived: optical AND weight",IF(OR(AB13=1,AC13=1),"Partial detection only","No detection")))) | AH13: =IF(B13<>"Sensor Snapshot","",IF(ISNUMBER(AG13),IF(AG13<0,"",IF(AG13>10,AG13/'02_Parameters'!$B$17,AG13)),"")) | AI13: =IF(B13<>"Sensor Snapshot","",IF(AG13="","Missing",IF(AG13<0,"Invalid negative flow",IF(AG13>10,"Normalized from high-scale log","Valid")))) | AJ13: =IF(B13<>"Sensor Snapshot","",--(L13="PUMPING")) | AK13: =IF(B13<>"Sensor Snapshot","",--(L13="HUMIDIFYING")) | AM13: =IF(B13<>"Sensor Snapshot","",--(OR(L13="FIRE_DETECTED",L13="BLOCKED"))) | AN13: =IF(B13<>"Sensor Snapshot","",--(N13>='02_Parameters'!$B$13)) | AO13: =IF(B13<>"Sensor Snapshot","",--(AND(L13="PUMPING",ISNUMBER(AH13),AH13<='02_Parameters'!$B$10))) | AP13: 500 | AQ13: =IF(B13="Calibration Trial",X13-AP13,"") -> -493.2476 | AR13: =IF(AND(B13="Calibration Trial",AP13<>0),AQ13/AP13*100,"") -> -98.64952 | AS13: 1 | AT13: 5 | AU13: g | AV13: ok | AW13: Signed reading preserved; positive magnitude used for calibration analysis | AX13: =IF(B13<>"Sensor Snapshot","",IF(P13<>"",20,0)+IF(T13<>"",20,0)+IF(X13<>"",20,0)+IF(AB13<>"",20,0)+IF(AH13<>"",20,0)) | AY13: =IF(AX13="","",IF(AX13>=90,"A",IF(AX13>=75,"B",IF(AX13>=60,"C","D")))) | AZ13: Compliant: load cell calibrated only for entry-platform presence detection | BA13: Original error columns are retained in the raw sheet; recalculated error uses positive magnitude.
A14: REC-0012 | B14: Calibration Trial | C14: 25536 | D14: =IF(ISNUMBER(C14),C14/1000,"") -> 25.536 | E14: CALIB | F14: 5 | G14: Entry Security | H14: LOADCELL | I14: Load-Cell Calibration | J14: Known reference weight test on entry platform | M14: =IF(L14="IDLE",0,IF(L14="FIRE_DETECTED",1,IF(L14="PUMPING",2,IF(L14="BLOCKED",3,IF(L14="HUMIDIFYING",4,IF(L14="STABLE",5,"")))))) | P14: =IF(AND(ISNUMBER(O14),O14<>-1,O14>='02_Parameters'!$B$18,O14<='02_Parameters'!$B$19),O14,"") | R14: =IF(B14<>"Sensor Snapshot","",IF(O14="","Missing",IF(O14=-1,"Sensor failure sentinel (-1)",IF(OR(O14<'02_Parameters'!$B$18,O14>'02_Parameters'!$B$19),"Out of accepted range","Valid")))) | T14: =IF(AND(ISNUMBER(S14),S14<>-1,S14>='02_Parameters'!$B$20,S14<='02_Parameters'!$B$21),S14,"") | V14: =IF(B14<>"Sensor Snapshot","",IF(S14="","Missing",IF(S14=-1,"Sensor failure sentinel (-1)",IF(OR(S14<'02_Parameters'!$B$20,S14>'02_Parameters'!$B$21),"Out of accepted range","Valid")))) | W14: 10.5881 | X14: =IF(ISNUMBER(W14),ABS(W14),"") -> 10.5881 | Y14: =IF(B14="Calibration Trial","Calibration magnitude",IF(B14<>"Sensor Snapshot","",IF(W14="","Missing",IF(W14<0,"Sign corrected to positive","Valid")))) -> Calibration magnitude | AB14: =IF(B14<>"Sensor Snapshot","",IF(ISNUMBER(AA14),--(AA14<>0),IF(ISNUMBER(Z14),--(Z14<'02_Parameters'!$B$15),""))) | AC14: =IF(B14<>"Sensor Snapshot","",IF(ISNUMBER(X14),--(X14>='02_Parameters'!$B$16),"")) | AD14: 0 | AE14: =IF(B14<>"Sensor Snapshot","",IF(AD14=1,1,IF(AND(AB14=1,AC14=1),1,0))) | AF14: =IF(B14<>"Sensor Snapshot","",IF(AD14=1,"Logged dual-sensor event",IF(AE14=1,"Derived: optical AND weight",IF(OR(AB14=1,AC14=1),"Partial detection only","No detection")))) | AH14: =IF(B14<>"Sensor Snapshot","",IF(ISNUMBER(AG14),IF(AG14<0,"",IF(AG14>10,AG14/'02_Parameters'!$B$17,AG14)),"")) | AI14: =IF(B14<>"Sensor Snapshot","",IF(AG14="","Missing",IF(AG14<0,"Invalid negative flow",IF(AG14>10,"Normalized from high-scale log","Valid")))) | AJ14: =IF(B14<>"Sensor Snapshot","",--(L14="PUMPING")) | AK14: =IF(B14<>"Sensor Snapshot","",--(L14="HUMIDIFYING")) | AM14: =IF(B14<>"Sensor Snapshot","",--(OR(L14="FIRE_DETECTED",L14="BLOCKED"))) | AN14: =IF(B14<>"Sensor Snapshot","",--(N14>='02_Parameters'!$B$13)) | AO14: =IF(B14<>"Sensor Snapshot","",--(AND(L14="PUMPING",ISNUMBER(AH14),AH14<='02_Parameters'!$B$10))) | AP14: 1000 | AQ14: =IF(B14="Calibration Trial",X14-AP14,"") -> -989.4119 | AR14: =IF(AND(B14="Calibration Trial",AP14<>0),AQ14/AP14*100,"") -> -98.94119 | AS14: 2 | AT14: 1 | AU14: g | AV14: ok | AW14: Signed reading preserved; positive magnitude used for calibration analysis | AX14: =IF(B14<>"Sensor Snapshot","",IF(P14<>"",20,0)+IF(T14<>"",20,0)+IF(X14<>"",20,0)+IF(AB14<>"",20,0)+IF(AH14<>"",20,0)) | AY14: =IF(AX14="","",IF(AX14>=90,"A",IF(AX14>=75,"B",IF(AX14>=60,"C","D")))) | AZ14: Compliant: load cell calibrated only for entry-platform presence detection | BA14: Original error columns are retained in the raw sheet; recalculated error uses positive magnitude.
A15: REC-0013 | B15: Calibration Trial | C15: 25852 | D15: =IF(ISNUMBER(C15),C15/1000,"") -> 25.852 | E15: CALIB | F15: 6 | G15: Entry Security | H15: LOADCELL | I15: Load-Cell Calibration | J15: Known reference weight test on entry platform | M15: =IF(L15="IDLE",0,IF(L15="FIRE_DETECTED",1,IF(L15="PUMPING",2,IF(L15="BLOCKED",3,IF(L15="HUMIDIFYING",4,IF(L15="STABLE",5,"")))))) | P15: =IF(AND(ISNUMBER(O15),O15<>-1,O15>='02_Parameters'!$B$18,O15<='02_Parameters'!$B$19),O15,"") | R15: =IF(B15<>"Sensor Snapshot","",IF(O15="","Missing",IF(O15=-1,"Sensor failure sentinel (-1)",IF(OR(O15<'02_Parameters'!$B$18,O15>'02_Parameters'!$B$19),"Out of accepted range","Valid")))) | T15: =IF(AND(ISNUMBER(S15),S15<>-1,S15>='02_Parameters'!$B$20,S15<='02_Parameters'!$B$21),S15,"") | V15: =IF(B15<>"Sensor Snapshot","",IF(S15="","Missing",IF(S15=-1,"Sensor failure sentinel (-1)",IF(OR(S15<'02_Parameters'!$B$20,S15>'02_Parameters'!$B$21),"Out of accepted range","Valid")))) | W15: 12.7286 | X15: =IF(ISNUMBER(W15),ABS(W15),"") -> 12.7286 | Y15: =IF(B15="Calibration Trial","Calibration magnitude",IF(B15<>"Sensor Snapshot","",IF(W15="","Missing",IF(W15<0,"Sign corrected to positive","Valid")))) -> Calibration magnitude | AB15: =IF(B15<>"Sensor Snapshot","",IF(ISNUMBER(AA15),--(AA15<>0),IF(ISNUMBER(Z15),--(Z15<'02_Parameters'!$B$15),""))) | AC15: =IF(B15<>"Sensor Snapshot","",IF(ISNUMBER(X15),--(X15>='02_Parameters'!$B$16),"")) | AD15: 0 | AE15: =IF(B15<>"Sensor Snapshot","",IF(AD15=1,1,IF(AND(AB15=1,AC15=1),1,0))) | AF15: =IF(B15<>"Sensor Snapshot","",IF(AD15=1,"Logged dual-sensor event",IF(AE15=1,"Derived: optical AND weight",IF(OR(AB15=1,AC15=1),"Partial detection only","No detection")))) | AH15: =IF(B15<>"Sensor Snapshot","",IF(ISNUMBER(AG15),IF(AG15<0,"",IF(AG15>10,AG15/'02_Parameters'!$B$17,AG15)),"")) | AI15: =IF(B15<>"Sensor Snapshot","",IF(AG15="","Missing",IF(AG15<0,"Invalid negative flow",IF(AG15>10,"Normalized from high-scale log","Valid")))) | AJ15: =IF(B15<>"Sensor Snapshot","",--(L15="PUMPING")) | AK15: =IF(B15<>"Sensor Snapshot","",--(L15="HUMIDIFYING")) | AM15: =IF(B15<>"Sensor Snapshot","",--(OR(L15="FIRE_DETECTED",L15="BLOCKED"))) | AN15: =IF(B15<>"Sensor Snapshot","",--(N15>='02_Parameters'!$B$13)) | AO15: =IF(B15<>"Sensor Snapshot","",--(AND(L15="PUMPING",ISNUMBER(AH15),AH15<='02_Parameters'!$B$10))) | AP15: 1000 | AQ15: =IF(B15="Calibration Trial",X15-AP15,"") -> -987.2714 | AR15: =IF(AND(B15="Calibration Trial",AP15<>0),AQ15/AP15*100,"") -> -98.72714 | AS15: 2 | AT15: 2 | AU15: g | AV15: ok | AW15: Signed reading preserved; positive magnitude used for calibration analysis | AX15: =IF(B15<>"Sensor Snapshot","",IF(P15<>"",20,0)+IF(T15<>"",20,0)+IF(X15<>"",20,0)+IF(AB15<>"",20,0)+IF(AH15<>"",20,0)) | AY15: =IF(AX15="","",IF(AX15>=90,"A",IF(AX15>=75,"B",IF(AX15>=60,"C","D")))) | AZ15: Compliant: load cell calibrated only for entry-platform presence detection | BA15: Original error columns are retained in the raw sheet; recalculated error uses positive magnitude.
A16: REC-0014 | B16: Calibration Trial | C16: 26169 | D16: =IF(ISNUMBER(C16),C16/1000,"") -> 26.169 | E16: CALIB | F16: 7 | G16: Entry Security | H16: LOADCELL | I16: Load-Cell Calibration | J16: Known reference weight test on entry platform | M16: =IF(L16="IDLE",0,IF(L16="FIRE_DETECTED",1,IF(L16="PUMPING",2,IF(L16="BLOCKED",3,IF(L16="HUMIDIFYING",4,IF(L16="STABLE",5,"")))))) | P16: =IF(AND(ISNUMBER(O16),O16<>-1,O16>='02_Parameters'!$B$18,O16<='02_Parameters'!$B$19),O16,"") | R16: =IF(B16<>"Sensor Snapshot","",IF(O16="","Missing",IF(O16=-1,"Sensor failure sentinel (-1)",IF(OR(O16<'02_Parameters'!$B$18,O16>'02_Parameters'!$B$19),"Out of accepted range","Valid")))) | T16: =IF(AND(ISNUMBER(S16),S16<>-1,S16>='02_Parameters'!$B$20,S16<='02_Parameters'!$B$21),S16,"") | V16: =IF(B16<>"Sensor Snapshot","",IF(S16="","Missing",IF(S16=-1,"Sensor failure sentinel (-1)",IF(OR(S16<'02_Parameters'!$B$20,S16>'02_Parameters'!$B$21),"Out of accepted range","Valid")))) | W16: -1.7786 | X16: =IF(ISNUMBER(W16),ABS(W16),"") -> 1.7786 | Y16: =IF(B16="Calibration Trial","Calibration magnitude",IF(B16<>"Sensor Snapshot","",IF(W16="","Missing",IF(W16<0,"Sign corrected to positive","Valid")))) -> Calibration magnitude | AB16: =IF(B16<>"Sensor Snapshot","",IF(ISNUMBER(AA16),--(AA16<>0),IF(ISNUMBER(Z16),--(Z16<'02_Parameters'!$B$15),""))) | AC16: =IF(B16<>"Sensor Snapshot","",IF(ISNUMBER(X16),--(X16>='02_Parameters'!$B$16),"")) | AD16: 0 | AE16: =IF(B16<>"Sensor Snapshot","",IF(AD16=1,1,IF(AND(AB16=1,AC16=1),1,0))) | AF16: =IF(B16<>"Sensor Snapshot","",IF(AD16=1,"Logged dual-sensor event",IF(AE16=1,"Derived: optical AND weight",IF(OR(AB16=1,AC16=1),"Partial detection only","No detection")))) | AH16: =IF(B16<>"Sensor Snapshot","",IF(ISNUMBER(AG16),IF(AG16<0,"",IF(AG16>10,AG16/'02_Parameters'!$B$17,AG16)),"")) | AI16: =IF(B16<>"Sensor Snapshot","",IF(AG16="","Missing",IF(AG16<0,"Invalid negative flow",IF(AG16>10,"Normalized from high-scale log","Valid")))) | AJ16: =IF(B16<>"Sensor Snapshot","",--(L16="PUMPING")) | AK16: =IF(B16<>"Sensor Snapshot","",--(L16="HUMIDIFYING")) | AM16: =IF(B16<>"Sensor Snapshot","",--(OR(L16="FIRE_DETECTED",L16="BLOCKED"))) | AN16: =IF(B16<>"Sensor Snapshot","",--(N16>='02_Parameters'!$B$13)) | AO16: =IF(B16<>"Sensor Snapshot","",--(AND(L16="PUMPING",ISNUMBER(AH16),AH16<='02_Parameters'!$B$10))) | AP16: 1000 | AQ16: =IF(B16="Calibration Trial",X16-AP16,"") -> -998.2214 | AR16: =IF(AND(B16="Calibration Trial",AP16<>0),AQ16/AP16*100,"") -> -99.82214 | AS16: 2 | AT16: 3 | AU16: g | AV16: ok | AW16: Signed reading preserved; positive magnitude used for calibration analysis | AX16: =IF(B16<>"Sensor Snapshot","",IF(P16<>"",20,0)+IF(T16<>"",20,0)+IF(X16<>"",20,0)+IF(AB16<>"",20,0)+IF(AH16<>"",20,0)) | AY16: =IF(AX16="","",IF(AX16>=90,"A",IF(AX16>=75,"B",IF(AX16>=60,"C","D")))) | AZ16: Compliant: load cell calibrated only for entry-platform presence detection | BA16: Original error columns are retained in the raw sheet; recalculated error uses positive magnitude.
A17: REC-0015 | B17: Calibration Trial | C17: 26487 | D17: =IF(ISNUMBER(C17),C17/1000,"") -> 26.487 | E17: CALIB | F17: 8 | G17: Entry Security | H17: LOADCELL | I17: Load-Cell Calibration | J17: Known reference weight test on entry platform | M17: =IF(L17="IDLE",0,IF(L17="FIRE_DETECTED",1,IF(L17="PUMPING",2,IF(L17="BLOCKED",3,IF(L17="HUMIDIFYING",4,IF(L17="STABLE",5,"")))))) | P17: =IF(AND(ISNUMBER(O17),O17<>-1,O17>='02_Parameters'!$B$18,O17<='02_Parameters'!$B$19),O17,"") | R17: =IF(B17<>"Sensor Snapshot","",IF(O17="","Missing",IF(O17=-1,"Sensor failure sentinel (-1)",IF(OR(O17<'02_Parameters'!$B$18,O17>'02_Parameters'!$B$19),"Out of accepted range","Valid")))) | T17: =IF(AND(ISNUMBER(S17),S17<>-1,S17>='02_Parameters'!$B$20,S17<='02_Parameters'!$B$21),S17,"") | V17: =IF(B17<>"Sensor Snapshot","",IF(S17="","Missing",IF(S17=-1,"Sensor failure sentinel (-1)",IF(OR(S17<'02_Parameters'!$B$20,S17>'02_Parameters'!$B$21),"Out of accepted range","Valid")))) | W17: -2.8143 | X17: =IF(ISNUMBER(W17),ABS(W17),"") -> 2.8143 | Y17: =IF(B17="Calibration Trial","Calibration magnitude",IF(B17<>"Sensor Snapshot","",IF(W17="","Missing",IF(W17<0,"Sign corrected to positive","Valid")))) -> Calibration magnitude | AB17: =IF(B17<>"Sensor Snapshot","",IF(ISNUMBER(AA17),--(AA17<>0),IF(ISNUMBER(Z17),--(Z17<'02_Parameters'!$B$15),""))) | AC17: =IF(B17<>"Sensor Snapshot","",IF(ISNUMBER(X17),--(X17>='02_Parameters'!$B$16),"")) | AD17: 0 | AE17: =IF(B17<>"Sensor Snapshot","",IF(AD17=1,1,IF(AND(AB17=1,AC17=1),1,0))) | AF17: =IF(B17<>"Sensor Snapshot","",IF(AD17=1,"Logged dual-sensor event",IF(AE17=1,"Derived: optical AND weight",IF(OR(AB17=1,AC17=1),"Partial detection only","No detection")))) | AH17: =IF(B17<>"Sensor Snapshot","",IF(ISNUMBER(AG17),IF(AG17<0,"",IF(AG17>10,AG17/'02_Parameters'!$B$17,AG17)),"")) | AI17: =IF(B17<>"Sensor Snapshot","",IF(AG17="","Missing",IF(AG17<0,"Invalid negative flow",IF(AG17>10,"Normalized from high-scale log","Valid")))) | AJ17: =IF(B17<>"Sensor Snapshot","",--(L17="PUMPING")) | AK17: =IF(B17<>"Sensor Snapshot","",--(L17="HUMIDIFYING")) | AM17: =IF(B17<>"Sensor Snapshot","",--(OR(L17="FIRE_DETECTED",L17="BLOCKED"))) | AN17: =IF(B17<>"Sensor Snapshot","",--(N17>='02_Parameters'!$B$13)) | AO17: =IF(B17<>"Sensor Snapshot","",--(AND(L17="PUMPING",ISNUMBER(AH17),AH17<='02_Parameters'!$B$10))) | AP17: 1000 | AQ17: =IF(B17="Calibration Trial",X17-AP17,"") -> -997.1857 | AR17: =IF(AND(B17="Calibration Trial",AP17<>0),AQ17/AP17*100,"") -> -99.71857 | AS17: 2 | AT17: 4 | AU17: g | AV17: ok | AW17: Signed reading preserved; positive magnitude used for calibration analysis | AX17: =IF(B17<>"Sensor Snapshot","",IF(P17<>"",20,0)+IF(T17<>"",20,0)+IF(X17<>"",20,0)+IF(AB17<>"",20,0)+IF(AH17<>"",20,0)) | AY17: =IF(AX17="","",IF(AX17>=90,"A",IF(AX17>=75,"B",IF(AX17>=60,"C","D")))) | AZ17: Compliant: load cell calibrated only for entry-platform presence detection | BA17: Original error columns are retained in the raw sheet; recalculated error uses positive magnitude.
A18: REC-0016 | B18: Calibration Trial | C18: 26806 | D18: =IF(ISNUMBER(C18),C18/1000,"") -> 26.806 | E18: CALIB | F18: 9 | G18: Entry Security | H18: LOADCELL | I18: Load-Cell Calibration | J18: Known reference weight test on entry platform | M18: =IF(L18="IDLE",0,IF(L18="FIRE_DETECTED",1,IF(L18="PUMPING",2,IF(L18="BLOCKED",3,IF(L18="HUMIDIFYING",4,IF(L18="STABLE",5,"")))))) | P18: =IF(AND(ISNUMBER(O18),O18<>-1,O18>='02_Parameters'!$B$18,O18<='02_Parameters'!$B$19),O18,"") | R18: =IF(B18<>"Sensor Snapshot","",IF(O18="","Missing",IF(O18=-1,"Sensor failure sentinel (-1)",IF(OR(O18<'02_Parameters'!$B$18,O18>'02_Parameters'!$B$19),"Out of accepted range","Valid")))) | T18: =IF(AND(ISNUMBER(S18),S18<>-1,S18>='02_Parameters'!$B$20,S18<='02_Parameters'!$B$21),S18,"") | V18: =IF(B18<>"Sensor Snapshot","",IF(S18="","Missing",IF(S18=-1,"Sensor failure sentinel (-1)",IF(OR(S18<'02_Parameters'!$B$20,S18>'02_Parameters'!$B$21),"Out of accepted range","Valid")))) | W18: -3.0857 | X18: =IF(ISNUMBER(W18),ABS(W18),"") -> 3.0857 | Y18: =IF(B18="Calibration Trial","Calibration magnitude",IF(B18<>"Sensor Snapshot","",IF(W18="","Missing",IF(W18<0,"Sign corrected to positive","Valid")))) -> Calibration magnitude | AB18: =IF(B18<>"Sensor Snapshot","",IF(ISNUMBER(AA18),--(AA18<>0),IF(ISNUMBER(Z18),--(Z18<'02_Parameters'!$B$15),""))) | AC18: =IF(B18<>"Sensor Snapshot","",IF(ISNUMBER(X18),--(X18>='02_Parameters'!$B$16),"")) | AD18: 0 | AE18: =IF(B18<>"Sensor Snapshot","",IF(AD18=1,1,IF(AND(AB18=1,AC18=1),1,0))) | AF18: =IF(B18<>"Sensor Snapshot","",IF(AD18=1,"Logged dual-sensor event",IF(AE18=1,"Derived: optical AND weight",IF(OR(AB18=1,AC18=1),"Partial detection only","No detection")))) | AH18: =IF(B18<>"Sensor Snapshot","",IF(ISNUMBER(AG18),IF(AG18<0,"",IF(AG18>10,AG18/'02_Parameters'!$B$17,AG18)),"")) | AI18: =IF(B18<>"Sensor Snapshot","",IF(AG18="","Missing",IF(AG18<0,"Invalid negative flow",IF(AG18>10,"Normalized from high-scale log","Valid")))) | AJ18: =IF(B18<>"Sensor Snapshot","",--(L18="PUMPING")) | AK18: =IF(B18<>"Sensor Snapshot","",--(L18="HUMIDIFYING")) | AM18: =IF(B18<>"Sensor Snapshot","",--(OR(L18="FIRE_DETECTED",L18="BLOCKED"))) | AN18: =IF(B18<>"Sensor Snapshot","",--(N18>='02_Parameters'!$B$13)) | AO18: =IF(B18<>"Sensor Snapshot","",--(AND(L18="PUMPING",ISNUMBER(AH18),AH18<='02_Parameters'!$B$10))) | AP18: 1000 | AQ18: =IF(B18="Calibration Trial",X18-AP18,"") -> -996.9143 | AR18: =IF(AND(B18="Calibration Trial",AP18<>0),AQ18/AP18*100,"") -> -99.69143 | AS18: 2 | AT18: 5 | AU18: g | AV18: ok | AW18: Signed reading preserved; positive magnitude used for calibration analysis | AX18: =IF(B18<>"Sensor Snapshot","",IF(P18<>"",20,0)+IF(T18<>"",20,0)+IF(X18<>"",20,0)+IF(AB18<>"",20,0)+IF(AH18<>"",20,0)) | AY18: =IF(AX18="","",IF(AX18>=90,"A",IF(AX18>=75,"B",IF(AX18>=60,"C","D")))) | AZ18: Compliant: load cell calibrated only for entry-platform presence detection | BA18: Original error columns are retained in the raw sheet; recalculated error uses positive magnitude.
A19: REC-0017 | B19: Calibration Trial | C19: 27124 | D19: =IF(ISNUMBER(C19),C19/1000,"") -> 27.124 | E19: CALIB | F19: 10 | G19: Entry Security | H19: LOADCELL | I19: Load-Cell Calibration | J19: Known reference weight test on entry platform | M19: =IF(L19="IDLE",0,IF(L19="FIRE_DETECTED",1,IF(L19="PUMPING",2,IF(L19="BLOCKED",3,IF(L19="HUMIDIFYING",4,IF(L19="STABLE",5,"")))))) | P19: =IF(AND(ISNUMBER(O19),O19<>-1,O19>='02_Parameters'!$B$18,O19<='02_Parameters'!$B$19),O19,"") | R19: =IF(B19<>"Sensor Snapshot","",IF(O19="","Missing",IF(O19=-1,"Sensor failure sentinel (-1)",IF(OR(O19<'02_Parameters'!$B$18,O19>'02_Parameters'!$B$19),"Out of accepted range","Valid")))) | T19: =IF(AND(ISNUMBER(S19),S19<>-1,S19>='02_Parameters'!$B$20,S19<='02_Parameters'!$B$21),S19,"") | V19: =IF(B19<>"Sensor Snapshot","",IF(S19="","Missing",IF(S19=-1,"Sensor failure sentinel (-1)",IF(OR(S19<'02_Parameters'!$B$20,S19>'02_Parameters'!$B$21),"Out of accepted range","Valid")))) | W19: -3.1167 | X19: =IF(ISNUMBER(W19),ABS(W19),"") -> 3.1167 | Y19: =IF(B19="Calibration Trial","Calibration magnitude",IF(B19<>"Sensor Snapshot","",IF(W19="","Missing",IF(W19<0,"Sign corrected to positive","Valid")))) -> Calibration magnitude | AB19: =IF(B19<>"Sensor Snapshot","",IF(ISNUMBER(AA19),--(AA19<>0),IF(ISNUMBER(Z19),--(Z19<'02_Parameters'!$B$15),""))) | AC19: =IF(B19<>"Sensor Snapshot","",IF(ISNUMBER(X19),--(X19>='02_Parameters'!$B$16),"")) | AD19: 0 | AE19: =IF(B19<>"Sensor Snapshot","",IF(AD19=1,1,IF(AND(AB19=1,AC19=1),1,0))) | AF19: =IF(B19<>"Sensor Snapshot","",IF(AD19=1,"Logged dual-sensor event",IF(AE19=1,"Derived: optical AND weight",IF(OR(AB19=1,AC19=1),"Partial detection only","No detection")))) | AH19: =IF(B19<>"Sensor Snapshot","",IF(ISNUMBER(AG19),IF(AG19<0,"",IF(AG19>10,AG19/'02_Parameters'!$B$17,AG19)),"")) | AI19: =IF(B19<>"Sensor Snapshot","",IF(AG19="","Missing",IF(AG19<0,"Invalid negative flow",IF(AG19>10,"Normalized from high-scale log","Valid")))) | AJ19: =IF(B19<>"Sensor Snapshot","",--(L19="PUMPING")) | AK19: =IF(B19<>"Sensor Snapshot","",--(L19="HUMIDIFYING")) | AM19: =IF(B19<>"Sensor Snapshot","",--(OR(L19="FIRE_DETECTED",L19="BLOCKED"))) | AN19: =IF(B19<>"Sensor Snapshot","",--(N19>='02_Parameters'!$B$13)) | AO19: =IF(B19<>"Sensor Snapshot","",--(AND(L19="PUMPING",ISNUMBER(AH19),AH19<='02_Parameters'!$B$10))) | AP19: 2000 | AQ19: =IF(B19="Calibration Trial",X19-AP19,"") -> -1996.8833 | AR19: =IF(AND(B19="Calibration Trial",AP19<>0),AQ19/AP19*100,"") -> -99.844165 | AS19: 3 | AT19: 1 | AU19: g | AV19: ok | AW19: Signed reading preserved; positive magnitude used for calibration analysis | AX19: =IF(B19<>"Sensor Snapshot","",IF(P19<>"",20,0)+IF(T19<>"",20,0)+IF(X19<>"",20,0)+IF(AB19<>"",20,0)+IF(AH19<>"",20,0)) | AY19: =IF(AX19="","",IF(AX19>=90,"A",IF(AX19>=75,"B",IF(AX19>=60,"C","D")))) | AZ19: Compliant: load cell calibrated only for entry-platform presence detection | BA19: Original error columns are retained in the raw sheet; recalculated error uses positive magnitude.
